Workbook

Sheet P&L
A2: Profit and Loss - Current Month
A3: Reporting Book: | C3: SS
A4: As of Date: | C4: 46270
A5: Location: | C5: GLOBAL
A6: MES | C6: 1 | D6: 2 | E6: 3 | F6: 4 | G6: 5 | H6: 6 | I6: 7 | J6: 8 | K6: 9 | L6: 10 | M6: 11 | N6: 12 | O6: 13 | P6: 14 | Q6: 15 | R6: 16 | S6: 17 | T6: 18 | U6: 19 | V6: 20 | W6: 21 | X6: 22 | Y6: 23 | Z6: 24 | AA6: 25 | AB6: 26 | AC6: 27 | AD6: 28 | AE6: 29 | AF6: 30 | AG6: 31 | AH6: 32 | AI6: 33 | AJ6: 34 | AK6: 35 | AL6: 36 | AM6: 37 | AN6: 38 | AO6: 39 | AP6: 40 | AQ6: 41 | AR6: 42 | AS6: 43 | AT6: 44 | AU6: 45 | AV6: 46 | AW6: 47 | AX6: 48 | AY6: 49 | AZ6: 50 | BA6: 51 | BB6: 52 | BC6: 53 | BD6: 54 | BE6: 55 | BF6: 56 | BG6: 57 | BH6: 58 | BI6: 59 | BJ6: 60 | BK6: 61 | BL6: 62 | BM6: 63 | BN6: 64 | BO6: 65 | BP6: 66 | BQ6: 67 | BR6: 68 | BS6: 69 | BT6: 70 | BU6: 71 | BV6: 72 | BW6: TOTAL
A7: Service per Month | C7: 0 | D7: 0 | E7: 0 | F7: 0 | G7: 0 | H7: 0 | I7: 150 | J7: 1100 | K7: 9666 | L7: 9776 | M7: 9821 | N7: 10854 | O7: 11606 | P7: 20415 | Q7: 27297 | R7: 39496 | S7: 39614 | T7: 87668 | U7: 87839 | V7: 104910 | W7: 105143 | X7: 105371 | Y7: 105610 | Z7: 105849 | AA7: 122084 | AB7: 122340 | AC7: 125593 | AD7: 125876 | AE7: 126164 | AF7: 126445 | AG7: 126732 | AH7: 127022 | AI7: 127313 | AJ7: 127602 | AK7: 127894 | AL7: 128192 | AM7: 128483 | AN7: 128783 | AO7: 129083 | AP7: 129380 | AQ7: 129685 | AR7: 129988 | AS7: 130291 | AT7: 130600 | AU7: 130905 | AV7: 131218 | AW7: 131530 | AX7: 131839 | AY7: 132155 | AZ7: 132474 | BA7: 132788 | BB7: 133108 | BC7: 133430 | BD7: 133754 | BE7: 134080 | BF7: 134406 | BG7: 134734 | BH7: 135066 | BI7: 135398 | BJ7: 135734 | BK7: 136066 | BL7: 136403 | BM7: 136743 | BN7: 137087 | BO7: 137429 | BP7: 137775 | BQ7: 138122 | BR7: 138473 | BS7: 138823 | BT7: 139176 | BU7: 139532 | BV7: 139889 | BW7: =SUM(C7:BV7) -> 7219872
A8: Revenue
C9: ='1_SEGUROS MONTERREY 🇲🇽'!B12 -> 0 | D9: ='1_SEGUROS MONTERREY 🇲🇽'!C12 -> 0 | E9: ='1_SEGUROS MONTERREY 🇲🇽'!D12 -> 0 | F9: ='1_SEGUROS MONTERREY 🇲🇽'!E12 -> 0 | G9: ='1_SEGUROS MONTERREY 🇲🇽'!F12 -> 0 | H9: ='1_SEGUROS MONTERREY 🇲🇽'!G12 -> 0 | I9: ='1_SEGUROS MONTERREY 🇲🇽'!H12 -> 0 | J9: ='1_SEGUROS MONTERREY 🇲🇽'!I12 -> 0 | ... BV9: ='1_SEGUROS MONTERREY 🇲🇽'!BU12 -> 72217
A10: ='2_SEGUROS MONTERREY 🇲🇽 - Hog'!A1 -> SEGUROS MONTERREY 🇲🇽 - Hogar | C10: ='2_SEGUROS MONTERREY 🇲🇽 - Hog'!B12 -> 0 | D10: ='2_SEGUROS MONTERREY 🇲🇽 - Hog'!C12 -> 0 | E10: ='2_SEGUROS MONTERREY 🇲🇽 - Hog'!D12 -> 0 | F10: ='2_SEGUROS MONTERREY 🇲🇽 - Hog'!E12 -> 0 | G10: ='2_SEGUROS MONTERREY 🇲🇽 - Hog'!F12 -> 0 | H10: ='2_SEGUROS MONTERREY 🇲🇽 - Hog'!G12 -> 0 | I10: ='2_SEGUROS MONTERREY 🇲🇽 - Hog'!H12 -> 0 | J10: ='2_SEGUROS MONTERREY 🇲🇽 - Hog'!I12 -> 0 | ... BV10: ='2_SEGUROS MONTERREY 🇲🇽 - Hog'!BU12 -> 30333
A11: ='3_CHUBB'!A1 -> CHUBB | C11: ='3_CHUBB'!B12 -> 0 | D11: ='3_CHUBB'!C12 -> 0 | E11: ='3_CHUBB'!D12 -> 0 | F11: ='3_CHUBB'!E12 -> 0 | G11: ='3_CHUBB'!F12 -> 0 | H11: ='3_CHUBB'!G12 -> 0 | I11: ='3_CHUBB'!H12 -> 0 | J11: ='3_CHUBB'!I12 -> 0 | ... BV11: ='3_CHUBB'!BU12 -> 988807
A12: ='4_CHUBB - Hogar Singapur'!A1 -> CHUBB - Hogar Singapur | C12: ='4_CHUBB - Hogar Singapur'!B12 -> 0 | D12: ='4_CHUBB - Hogar Singapur'!C12 -> 0 | E12: ='4_CHUBB - Hogar Singapur'!D12 -> 0 | F12: ='4_CHUBB - Hogar Singapur'!E12 -> 0 | G12: ='4_CHUBB - Hogar Singapur'!F12 -> 0 | H12: ='4_CHUBB - Hogar Singapur'!G12 -> 0 | I12: ='4_CHUBB - Hogar Singapur'!H12 -> 0 | J12: ='4_CHUBB - Hogar Singapur'!I12 -> 21000 | ... BV12: ='4_CHUBB - Hogar Singapur'!BU12 -> 23792
A13: ='5_CHUBB · Hogar Perú'!A1 -> Actor: CHUBB · Hogar Perú | C13: ='5_CHUBB · Hogar Perú'!B12 -> 0 | D13: ='5_CHUBB · Hogar Perú'!C12 -> 0 | E13: ='5_CHUBB · Hogar Perú'!D12 -> 0 | F13: ='5_CHUBB · Hogar Perú'!E12 -> 0 | G13: ='5_CHUBB · Hogar Perú'!F12 -> 0 | H13: ='5_CHUBB · Hogar Perú'!G12 -> 0 | I13: ='5_CHUBB · Hogar Perú'!H12 -> 6750 | J13: ='5_CHUBB · Hogar Perú'!I12 -> 6763 | ... BV13: ='5_CHUBB · Hogar Perú'!BU12 -> 7662
A14: ='6_CHUBB · Salud Chile'!A1 -> Actor: CHUBB · Salud Chile | C14: ='6_CHUBB · Salud Chile'!B12 -> 0 | D14: ='6_CHUBB · Salud Chile'!C12 -> 0 | E14: ='6_CHUBB · Salud Chile'!D12 -> 0 | F14: ='6_CHUBB · Salud Chile'!E12 -> 0 | G14: ='6_CHUBB · Salud Chile'!F12 -> 0 | H14: ='6_CHUBB · Salud Chile'!G12 -> 0 | I14: ='6_CHUBB · Salud Chile'!H12 -> 0 | J14: ='6_CHUBB · Salud Chile'!I12 -> 0 | ... BV14: ='6_CHUBB · Salud Chile'!BU12 -> 24876
A15: ='7_CHUBB - Salud Singapur'!A1 -> Actor: CHUBB - Salud Singapur | C15: ='7_CHUBB - Salud Singapur'!B12 -> 0 | D15: ='7_CHUBB - Salud Singapur'!C12 -> 0 | E15: ='7_CHUBB - Salud Singapur'!D12 -> 0 | F15: ='7_CHUBB - Salud Singapur'!E12 -> 0 | G15: ='7_CHUBB - Salud Singapur'!F12 -> 0 | H15: ='7_CHUBB - Salud Singapur'!G12 -> 0 | I15: ='7_CHUBB - Salud Singapur'!H12 -> 0 | J15: ='7_CHUBB - Salud Singapur'!I12 -> 0 | ... BV15: ='7_CHUBB - Salud Singapur'!BU12 -> 8633
A16: ='8_Kanguro Insurance'!A1 -> Actor: Kanguro Insurance | C16: ='8_Kanguro Insurance'!B12 -> 0 | D16: ='8_Kanguro Insurance'!C12 -> 0 | E16: ='8_Kanguro Insurance'!D12 -> 0 | F16: ='8_Kanguro Insurance'!E12 -> 0 | G16: ='8_Kanguro Insurance'!F12 -> 0 | H16: ='8_Kanguro Insurance'!G12 -> 0 | I16: ='8_Kanguro Insurance'!H12 -> 0 | J16: ='8_Kanguro Insurance'!I12 -> 22000 | ... BV16: ='8_Kanguro Insurance'!BU12 -> 49339
A17: ='9_Kanguro Insurance - Hogar'!A1 -> Actor: Kanguro Insurance - Hogar | C17: ='9_Kanguro Insurance - Hogar'!B12 -> 0 | D17: ='9_Kanguro Insurance - Hogar'!C12 -> 0 | E17: ='9_Kanguro Insurance - Hogar'!D12 -> 0 | F17: ='9_Kanguro Insurance - Hogar'!E12 -> 0 | G17: ='9_Kanguro Insurance - Hogar'!F12 -> 0 | H17: ='9_Kanguro Insurance - Hogar'!G12 -> 0 | I17: ='9_Kanguro Insurance - Hogar'!H12 -> 0 | J17: ='9_Kanguro Insurance - Hogar'!I12 -> 0 | ... BV17: ='9_Kanguro Insurance - Hogar'!BU12 -> 22961
A18: ='10_METLIFE'!A1 -> Actor: METLIFE | C18: ='10_METLIFE'!B12 -> 0 | D18: ='10_METLIFE'!C12 -> 0 | E18: ='10_METLIFE'!D12 -> 0 | F18: ='10_METLIFE'!E12 -> 0 | G18: ='10_METLIFE'!F12 -> 0 | H18: ='10_METLIFE'!G12 -> 0 | I18: ='10_METLIFE'!H12 -> 0 | J18: ='10_METLIFE'!I12 -> 31500 | ... BV18: ='10_METLIFE'!BU12 -> 35687
A19: ='11_METLIFE - Salud'!A1 -> Actor: METLIFE - Salud | C19: ='11_METLIFE - Salud'!B12 -> 0 | D19: ='11_METLIFE - Salud'!C12 -> 0 | E19: ='11_METLIFE - Salud'!D12 -> 0 | F19: ='11_METLIFE - Salud'!E12 -> 0 | G19: ='11_METLIFE - Salud'!F12 -> 0 | H19: ='11_METLIFE - Salud'!G12 -> 0 | I19: ='11_METLIFE - Salud'!H12 -> 0 | J19: ='11_METLIFE - Salud'!I12 -> 0 | ... BV19: ='11_METLIFE - Salud'!BU12 -> 33443
A20: ='12_Seguros Mundial 🇨🇴'!A1 -> Actor: Seguros Mundial 🇨🇴 | C20: ='12_Seguros Mundial 🇨🇴'!B12 -> 0 | D20: ='12_Seguros Mundial 🇨🇴'!C12 -> 0 | E20: ='12_Seguros Mundial 🇨🇴'!D12 -> 0 | F20: ='12_Seguros Mundial 🇨🇴'!E12 -> 0 | G20: ='12_Seguros Mundial 🇨🇴'!F12 -> 0 | H20: ='12_Seguros Mundial 🇨🇴'!G12 -> 0 | I20: ='12_Seguros Mundial 🇨🇴'!H12 -> 0 | J20: ='12_Seguros Mundial 🇨🇴'!I12 -> 0 | ... BV20: ='12_Seguros Mundial 🇨🇴'!BU12 -> 29860
A21: ='13_Seguros Mundial 🇨🇴 - Hogar'!A1 -> Actor: Seguros Mundial 🇨🇴 - Hogar | C21: ='13_Seguros Mundial 🇨🇴 - Hogar'!B12 -> 0 | D21: ='13_Seguros Mundial 🇨🇴 - Hogar'!C12 -> 0 | E21: ='13_Seguros Mundial 🇨🇴 - Hogar'!D12 -> 0 | F21: ='13_Seguros Mundial 🇨🇴 - Hogar'!E12 -> 0 | G21: ='13_Seguros Mundial 🇨🇴 - Hogar'!F12 -> 0 | H21: ='13_Seguros Mundial 🇨🇴 - Hogar'!G12 -> 0 | I21: ='13_Seguros Mundial 🇨🇴 - Hogar'!H12 -> 0 | J21: ='13_Seguros Mundial 🇨🇴 - Hogar'!I12 -> 0 | ... BV21: ='13_Seguros Mundial 🇨🇴 - Hogar'!BU12 -> 2886
A22: ='14_BNP Paribas Cardif'!A1 -> Actor: BNP Paribas Cardif | C22: ='14_BNP Paribas Cardif'!B12 -> 0 | D22: ='14_BNP Paribas Cardif'!C12 -> 0 | E22: ='14_BNP Paribas Cardif'!D12 -> 0 | F22: ='14_BNP Paribas Cardif'!E12 -> 0 | G22: ='14_BNP Paribas Cardif'!F12 -> 0 | H22: ='14_BNP Paribas Cardif'!G12 -> 0 | I22: ='14_BNP Paribas Cardif'!H12 -> 0 | J22: ='14_BNP Paribas Cardif'!I12 -> 0 | ... BV22: ='14_BNP Paribas Cardif'!BU12 -> 25030
A23: ='15_BNP Paribas Cardif - Hogar P'!A1 -> Actor: BNP Paribas Cardif - Hogar Perú | C23: ='15_BNP Paribas Cardif - Hogar P'!B12 -> 0 | D23: ='15_BNP Paribas Cardif - Hogar P'!C12 -> 0 | E23: ='15_BNP Paribas Cardif - Hogar P'!D12 -> 0 | F23: ='15_BNP Paribas Cardif - Hogar P'!E12 -> 0 | G23: ='15_BNP Paribas Cardif - Hogar P'!F12 -> 0 | H23: ='15_BNP Paribas Cardif - Hogar P'!G12 -> 0 | I23: ='15_BNP Paribas Cardif - Hogar P'!H12 -> 0 | J23: ='15_BNP Paribas Cardif - Hogar P'!I12 -> 0 | ... BV23: ='15_BNP Paribas Cardif - Hogar P'!BU12 -> 9270
A24: ='16_BNP Paribas Cardif - Vet Col'!A1 -> Actor: BNP Paribas Cardif - Vet Colombia | C24: ='16_BNP Paribas Cardif - Vet Col'!B12 -> 0 | D24: ='16_BNP Paribas Cardif - Vet Col'!C12 -> 0 | E24: ='16_BNP Paribas Cardif - Vet Col'!D12 -> 0 | F24: ='16_BNP Paribas Cardif - Vet Col'!E12 -> 0 | G24: ='16_BNP Paribas Cardif - Vet Col'!F12 -> 0 | H24: ='16_BNP Paribas Cardif - Vet Col'!G12 -> 0 | I24: ='16_BNP Paribas Cardif - Vet Col'!H12 -> 0 | J24: ='16_BNP Paribas Cardif - Vet Col'!I12 -> 0 | ... BV24: ='16_BNP Paribas Cardif - Vet Col'!BU12 -> 14219
A25: ='17_BNP Paribas Cardif - Salud M'!A1 -> Actor: BNP Paribas Cardif - Salud México | C25: ='17_BNP Paribas Cardif - Salud M'!B12 -> 0 | D25: ='17_BNP Paribas Cardif - Salud M'!C12 -> 0 | E25: ='17_BNP Paribas Cardif - Salud M'!D12 -> 0 | F25: ='17_BNP Paribas Cardif - Salud M'!E12 -> 0 | G25: ='17_BNP Paribas Cardif - Salud M'!F12 -> 0 | H25: ='17_BNP Paribas Cardif - Salud M'!G12 -> 0 | I25: ='17_BNP Paribas Cardif - Salud M'!H12 -> 0 | J25: ='17_BNP Paribas Cardif - Salud M'!I12 -> 0 | ... BV25: ='17_BNP Paribas Cardif - Salud M'!BU12 -> 23039
A26: ='18_BNP Paribas Cardif - Salud B'!A1 -> Actor: BNP Paribas Cardif - Salud Brasil | C26: ='18_BNP Paribas Cardif - Salud B'!B12 -> 0 | D26: ='18_BNP Paribas Cardif - Salud B'!C12 -> 0 | E26: ='18_BNP Paribas Cardif - Salud B'!D12 -> 0 | F26: ='18_BNP Paribas Cardif - Salud B'!E12 -> 0 | G26: ='18_BNP Paribas Cardif - Salud B'!F12 -> 0 | H26: ='18_BNP Paribas Cardif - Salud B'!G12 -> 0 | I26: ='18_BNP Paribas Cardif - Salud B'!H12 -> 0 | J26: ='18_BNP Paribas Cardif - Salud B'!I12 -> 0 | ... BV26: ='18_BNP Paribas Cardif - Salud B'!BU12 -> 268668
A27: ='19_Lemonade'!A1 -> Actor: Lemonade | C27: ='19_Lemonade'!B12 -> 0 | D27: ='19_Lemonade'!C12 -> 0 | E27: ='19_Lemonade'!D12 -> 0 | F27: ='19_Lemonade'!E12 -> 0 | G27: ='19_Lemonade'!F12 -> 0 | H27: ='19_Lemonade'!G12 -> 0 | I27: ='19_Lemonade'!H12 -> 0 | J27: ='19_Lemonade'!I12 -> 0 | ... BV27: ='19_Lemonade'!BU12 -> 808964
A28: ='20_Lemonade - Hogar'!A1 -> Actor: Lemonade - Hogar | C28: ='20_Lemonade - Hogar'!B12 -> 0 | D28: ='20_Lemonade - Hogar'!C12 -> 0 | E28: ='20_Lemonade - Hogar'!D12 -> 0 | F28: ='20_Lemonade - Hogar'!E12 -> 0 | G28: ='20_Lemonade - Hogar'!F12 -> 0 | H28: ='20_Lemonade - Hogar'!G12 -> 0 | I28: ='20_Lemonade - Hogar'!H12 -> 0 | J28: ='20_Lemonade - Hogar'!I12 -> 0 | ... BV28: ='20_Lemonade - Hogar'!BU12 -> 668616
A29: ='21_Consorcio'!A1 -> Actor: Consorcio | C29: ='21_Consorcio'!B12 -> 0 | D29: ='21_Consorcio'!C12 -> 0 | E29: ='21_Consorcio'!D12 -> 0 | F29: ='21_Consorcio'!E12 -> 0 | G29: ='21_Consorcio'!F12 -> 0 | H29: ='21_Consorcio'!G12 -> 0 | I29: ='21_Consorcio'!H12 -> 0 | J29: ='21_Consorcio'!I12 -> 0 | ... BV29: ='21_Consorcio'!BU12 -> 120246
A30: ='22_Consorcio - Hogar'!A1 -> Actor: Consorcio - Hogar | C30: ='22_Consorcio - Hogar'!B12 -> 0 | D30: ='22_Consorcio - Hogar'!C12 -> 0 | E30: ='22_Consorcio - Hogar'!D12 -> 0 | F30: ='22_Consorcio - Hogar'!E12 -> 0 | G30: ='22_Consorcio - Hogar'!F12 -> 0 | H30: ='22_Consorcio - Hogar'!G12 -> 0 | I30: ='22_Consorcio - Hogar'!H12 -> 0 | J30: ='22_Consorcio - Hogar'!I12 -> 0 | ... BV30: ='22_Consorcio - Hogar'!BU12 -> 37983
A31: ='23_Chilena Consolidada (Zurich)'!A1 -> Actor: Chilena Consolidada (Zurich) | C31: ='23_Chilena Consolidada (Zurich)'!B12 -> 0 | D31: ='23_Chilena Consolidada (Zurich)'!C12 -> 0 | E31: ='23_Chilena Consolidada (Zurich)'!D12 -> 0 | F31: ='23_Chilena Consolidada (Zurich)'!E12 -> 0 | G31: ='23_Chilena Consolidada (Zurich)'!F12 -> 0 | H31: ='23_Chilena Consolidada (Zurich)'!G12 -> 0 | I31: ='23_Chilena Consolidada (Zurich)'!H12 -> 0 | J31: ='23_Chilena Consolidada (Zurich)'!I12 -> 0 | ... BV31: ='23_Chilena Consolidada (Zurich)'!BU12 -> 360738
A32: ='24_Chilena Consolidada (Zurich)'!A1 -> Actor: Chilena Consolidada (Zurich) - Hogar | C32: ='24_Chilena Consolidada (Zurich)'!B12 -> 0 | D32: ='24_Chilena Consolidada (Zurich)'!C12 -> 0 | E32: ='24_Chilena Consolidada (Zurich)'!D12 -> 0 | F32: ='24_Chilena Consolidada (Zurich)'!E12 -> 0 | G32: ='24_Chilena Consolidada (Zurich)'!F12 -> 0 | H32: ='24_Chilena Consolidada (Zurich)'!G12 -> 0 | I32: ='24_Chilena Consolidada (Zurich)'!H12 -> 0 | J32: ='24_Chilena Consolidada (Zurich)'!I12 -> 0 | ... BV32: ='24_Chilena Consolidada (Zurich)'!BU12 -> 76112
A33: ='25_Allstate'!A1 -> Actor: Allstate | C33: ='25_Allstate'!B12 -> 0 | D33: ='25_Allstate'!C12 -> 0 | E33: ='25_Allstate'!D12 -> 0 | F33: ='25_Allstate'!E12 -> 0 | G33: ='25_Allstate'!F12 -> 0 | H33: ='25_Allstate'!G12 -> 0 | I33: ='25_Allstate'!H12 -> 0 | J33: ='25_Allstate'!I12 -> 0 | ... BV33: ='25_Allstate'!BU12 -> 2727445
A34: ='26_Allstate - Vehicular'!A1 -> Actor: Allstate - Vehicular | C34: ='26_Allstate - Vehicular'!B12 -> 0 | D34: ='26_Allstate - Vehicular'!C12 -> 0 | E34: ='26_Allstate - Vehicular'!D12 -> 0 | F34: ='26_Allstate - Vehicular'!E12 -> 0 | G34: ='26_Allstate - Vehicular'!F12 -> 0 | H34: ='26_Allstate - Vehicular'!G12 -> 0 | I34: ='26_Allstate - Vehicular'!H12 -> 0 | J34: ='26_Allstate - Vehicular'!I12 -> 0 | ... BV34: ='26_Allstate - Vehicular'!BU12 -> 1807064
A35: ='27_SURA Chile'!A1 -> Actor: SURA Chile | C35: ='27_SURA Chile'!B12 -> 0 | D35: ='27_SURA Chile'!C12 -> 0 | E35: ='27_SURA Chile'!D12 -> 0 | F35: ='27_SURA Chile'!E12 -> 0 | G35: ='27_SURA Chile'!F12 -> 0 | H35: ='27_SURA Chile'!G12 -> 0 | I35: ='27_SURA Chile'!H12 -> 0 | J35: ='27_SURA Chile'!I12 -> 0 | ... BV35: ='27_SURA Chile'!BU12 -> 379146
A36: ='28_SURA Chile - Hogar'!A1 -> Actor: SURA Chile - Hogar | C36: ='28_SURA Chile - Hogar'!B12 -> 0 | D36: ='28_SURA Chile - Hogar'!C12 -> 0 | E36: ='28_SURA Chile - Hogar'!D12 -> 0 | F36: ='28_SURA Chile - Hogar'!E12 -> 0 | G36: ='28_SURA Chile - Hogar'!F12 -> 0 | H36: ='28_SURA Chile - Hogar'!G12 -> 0 | I36: ='28_SURA Chile - Hogar'!H12 -> 0 | J36: ='28_SURA Chile - Hogar'!I12 -> 0 | ... BV36: ='28_SURA Chile - Hogar'!BU12 -> 132807
A37: ='29_SURA Colombia'!A1 -> Actor: SURA Colombia | C37: ='29_SURA Colombia'!B12 -> 0 | D37: ='29_SURA Colombia'!C12 -> 0 | E37: ='29_SURA Colombia'!D12 -> 0 | F37: ='29_SURA Colombia'!E12 -> 0 | G37: ='29_SURA Colombia'!F12 -> 0 | H37: ='29_SURA Colombia'!G12 -> 0 | I37: ='29_SURA Colombia'!H12 -> 0 | J37: ='29_SURA Colombia'!I12 -> 0 | ... BV37: ='29_SURA Colombia'!BU12 -> 460776
A38: ='30_SURA Colombia - Hogar'!A1 -> Actor: SURA Colombia - Hogar | C38: ='30_SURA Colombia - Hogar'!B12 -> 0 | D38: ='30_SURA Colombia - Hogar'!C12 -> 0 | E38: ='30_SURA Colombia - Hogar'!D12 -> 0 | F38: ='30_SURA Colombia - Hogar'!E12 -> 0 | G38: ='30_SURA Colombia - Hogar'!F12 -> 0 | H38: ='30_SURA Colombia - Hogar'!G12 -> 0 | I38: ='30_SURA Colombia - Hogar'!H12 -> 0 | J38: ='30_SURA Colombia - Hogar'!I12 -> 0 | ... BV38: ='30_SURA Colombia - Hogar'!BU12 -> 282726
A39: ='31_Liberty Mutual'!A1 -> Actor: Liberty Mutual | C39: ='31_Liberty Mutual'!B12 -> 0 | D39: ='31_Liberty Mutual'!C12 -> 0 | E39: ='31_Liberty Mutual'!D12 -> 0 | F39: ='31_Liberty Mutual'!E12 -> 0 | G39: ='31_Liberty Mutual'!F12 -> 0 | H39: ='31_Liberty Mutual'!G12 -> 0 | I39: ='31_Liberty Mutual'!H12 -> 0 | J39: ='31_Liberty Mutual'!I12 -> 0 | ... BV39: ='31_Liberty Mutual'!BU12 -> 1673652
A40: ='32_Liberty Mutual - Hogar'!A1 -> Actor: Liberty Mutual - Hogar | C40: ='32_Liberty Mutual - Hogar'!B12 -> 0 | D40: ='32_Liberty Mutual - Hogar'!C12 -> 0 | E40: ='32_Liberty Mutual - Hogar'!D12 -> 0 | F40: ='32_Liberty Mutual - Hogar'!E12 -> 0 | G40: ='32_Liberty Mutual - Hogar'!F12 -> 0 | H40: ='32_Liberty Mutual - Hogar'!G12 -> 0 | I40: ='32_Liberty Mutual - Hogar'!H12 -> 0 | J40: ='32_Liberty Mutual - Hogar'!I12 -> 0 | ... BV40: ='32_Liberty Mutual - Hogar'!BU12 -> 1655408
A42: Revenue - Services | C42: =SUM(C9:C41) -> 0 | D42: =SUM(D9:D41) -> 0 | E42: =SUM(E9:E41) -> 0 | F42: =SUM(F9:F41) -> 0 | G42: =SUM(G9:G41) -> 0 | H42: =SUM(H9:H41) -> 0 | I42: =SUM(I9:I41) -> 6750 | J42: =SUM(J9:J41) -> 81263 | ... BV42: =SUM(BV9:BV41) -> 12862405
...

Sheet Formulas
A1: Call Center 20% | C1: TOTAL SERVICES | E1: 0 | F1: 0 | G1: 0 | H1: 0 | I1: 0 | J1: 0 | K1: 150 | L1: 1100 | M1: 9666 | N1: 9776 | O1: 9821 | P1: 10854 | Q1: 11606 | R1: 20415 | S1: 27297 | T1: 39496 | U1: 39614 | V1: 87668 | W1: 87839 | X1: 104910 | Y1: 105143 | Z1: 105371 | AA1: 105610 | AB1: 105849 | AC1: 122084 | AD1: 122340 | AE1: 125593 | AF1: 125876 | AG1: 126164 | AH1: 126445 | AI1: 126732 | AJ1: 127022 | AK1: 127313 | AL1: 127602 | AM1: 127894 | AN1: 128192 | AO1: 128483 | AP1: 128783 | AQ1: 129083 | AR1: 129380 | AS1: 129685 | AT1: 129988 | AU1: 130291 | AV1: 130600 | AW1: 130905 | AX1: 131218 | AY1: 131530 | AZ1: 131839 | BA1: 132155 | BB1: 132474 | BC1: 132788 | BD1: 133108 | BE1: 133430 | BF1: 133754 | BG1: 134080 | BH1: 134406 | BI1: 134734 | BJ1: 135066 | BK1: 135398 | BL1: 135734 | BM1: 136066 | BN1: 136403 | BO1: 136743 | BP1: 137087 | BQ1: 137429 | BR1: 137775 | BS1: 138122 | BT1: 138473 | BU1: 138823 | BV1: 139176 | BW1: 139532 | BX1: 139889
B2: Unitary Cost | C2: % Ai free HR Assist
B3: 900 | C3: 0.2 | D3: 20% Services | E3: =E1*$C$3 -> 0 | F3: =F1*$C$3 -> 0 | G3: =G1*$C$3 -> 0 | H3: =H1*$C$3 -> 0 | I3: =I1*$C$3 -> 0 | J3: =J1*$C$3 -> 0 | K3: =K1*$C$3 -> 30 | L3: =L1*$C$3 -> 220 | ... BX3: =BX1*$C$3 -> 27977.8
C4: Cases per HR | D4: # HR Neccesary | E4: =E3/$C$5 -> 0 | F4: =F3/$C$5 -> 0 | G4: =G3/$C$5 -> 0 | H4: =H3/$C$5 -> 0 | I4: =I3/$C$5 -> 0 | J4: =J3/$C$5 -> 0 | K4: =K3/$C$5 -> 0.125 | L4: =L3/$C$5 -> 0.91666667 | ... BX4: =BX3/$C$5 -> 116.57417
C5: 240 | D5: Cost | E5: =E4*$B$3 -> 0 | F5: =F4*$B$3 -> 0 | G5: =G4*$B$3 -> 0 | H5: =H4*$B$3 -> 0 | I5: =I4*$B$3 -> 0 | J5: =J4*$B$3 -> 0 | K5: =K4*$B$3 -> 112.5 | L5: =L4*$B$3 -> 825 | ... BX5: =BX4*$B$3 -> 104916.75
A8: Call Center Office | C8: Cost per Position | D8: 100 | E8: =$D$8*E4 -> 0 | F8: =$D$8*F4 -> 0 | G8: =$D$8*G4 -> 0 | H8: =$D$8*H4 -> 0 | I8: =$D$8*I4 -> 0 | J8: =$D$8*J4 -> 0 | K8: =$D$8*K4 -> 12.5 | L8: =$D$8*L4 -> 91.666667 | ... BX8: =$D$8*BX4 -> 11657.417
A11: Costo de IA por llamada | B11: 📞 Twilio Incoming | C11: Transporte de la llamada telefónica | D11: 0.0945
B12: 🗣️ ElevenLabs Voice | C12: Escuchar al usuario y generar la voz de la IA | D12: 0.08
B13: 🧠 Qwen 3.5 | C13: El modelo que procesa la conversación y decide qué responder | D13: 0.028 | E13: Total Llamadas
B14: Record | C14: Grabacion de la llamada | D14: 0.0025 | E14: 1.5 | F14: Factor
B15: TOTAL / MIN | D15: =SUM(D11:D14) -> 0.205 | E15: =$E$14*E1 -> 0 | F15: =$E$14*F1 -> 0 | G15: =$E$14*G1 -> 0 | H15: =$E$14*H1 -> 0 | I15: =$E$14*I1 -> 0 | J15: =$E$14*J1 -> 0 | K15: =$E$14*K1 -> 225 | L15: =$E$14*L1 -> 1650 | ... BX15: =$E$14*BX1 -> 209833.5
B16: TMO / Minutos | C16: 7 | D16: =D15*C16 -> 1.435 | E16: =$D$16*E15 -> 0 | F16: =$D$16*F15 -> 0 | G16: =$D$16*G15 -> 0 | H16: =$D$16*H15 -> 0 | I16: =$D$16*I15 -> 0 | J16: =$D$16*J15 -> 0 | K16: =$D$16*K15 -> 322.875 | L16: =$D$16*L15 -> 2367.75 | ... BX16: =$D$16*BX15 -> 301111.07

Sheet Resumen
A1: Resumen general - Fee for Service
A3: Actor | B3: País | C3: Categoría | D3: Servicio | E3: Casos | F3: Revenue Total ($) | G3: Revenue Weso ($) | H3: Costos Proveedor ($) | I3: Ticket Prom. ($) | J3: Fee Prom. % | K3: Churn Acum.
A4: SEGUROS MONTERREY 🇲🇽 | B4: México | C4: Salud y cuidado | D4: Asistencia Médica Telefónica | E4: 105476 | F4: 4219054 | G4: 1393716 | H4: 2953338 | I4: 40 | J4: 30 | K4: 62203
A5: SEGUROS MONTERREY 🇲🇽 - Hogar | B5: México | C5: Hogar y Propiedades | E5: 33417 | F5: 1670870 | G5: 501261 | H5: 1169609 | I5: 50 | J5: 30 | K5: 11580
A6: CHUBB | B6: Estados Unidos | C6: Veterinario | E6: 494985 | F6: 54448342 | G6: 11017668 | H6: 43558673 | I6: 110 | J6: 20 | K6: 283498
A7: CHUBB - Hogar Singapur | B7: Singapur | C7: Hogar y Propiedades | E7: 20770 | F7: 1453867 | G7: 436160 | H7: 1017707 | I7: 70 | J7: 30 | K7: 10215
A8: CHUBB · Hogar Perú | B8: Perú | C8: Hogar y Propiedades | E8: 10555 | F8: 474977 | G8: 142493 | H8: 332484 | I8: 45 | J8: 30 | K8: 4154
A9: CHUBB · Salud Chile | B9: Chile | C9: Salud y cuidado | E9: 27240 | F9: 1498174 | G9: 449452 | H9: 1048722 | I9: 55 | J9: 30 | K9: 8036
A10: CHUBB - Salud Singapur | B10: Singapur | C10: Salud y cuidado | E10: 6212 | F10: 496998 | G10: 149099 | H10: 347898 | I10: 80 | J10: 30 | K10: 4578
A11: Kanguro Insurance | B11: Estados Unidos | C11: Veterinario | E11: 20019 | F11: 2202054 | G11: 570411 | H11: 1761643 | I11: 110 | J11: 20 | K11: 11742
A12: Kanguro Insurance - Hogar | B12: Estados Unidos | C12: Hogar y Propiedades | E12: 6695 | F12: 1004179 | G12: 301254 | H12: 702925 | I12: 150 | J12: 30 | K12: 5607
A13: METLIFE | B13: Chile | C13: Salud y cuidado | E13: 31154 | F13: 2180800 | G13: 784240 | H13: 1526560 | I13: 70 | J13: 30 | K13: 12258
A14: METLIFE - Salud | B14: Colombia | C14: Salud y cuidado | E14: 38504 | F14: 1925220 | G14: 577566 | H14: 1347654 | I14: 50 | J14: 30 | K14: 13354
A15: Seguros Mundial 🇨🇴 | B15: Colombia | C15: Asistencia en Ruta - Livianos | E15: 27008 | F15: 1620464 | G15: 604139 | H15: 1134325 | I15: 60 | J15: 30 | K15: 13255
A16: Seguros Mundial 🇨🇴 - Hogar | B16: Colombia | C16: Hogar y Propiedades | E16: 4217 | F16: 168675 | G16: 50602 | H16: 118072 | I16: 40 | J16: 30 | K16: 2418
... A35: Liberty Mutual - Hogar | B35: Estados Unidos | C35: Hogar y Propiedades | E35: 570590 | F35: 85588466 | G35: 17117693 | H35: 68470773 | I35: 150 | J35: 20 | K35: 479617
A36: TOTAL | E36: 7219860 | F36: 655824602 | G36: 146138466 | H36: 511216136 | I36: 90.84 | J36: 22.28 | K36: 4220222

Sheet Por Categoría
A1: Categoría | B1: Casos | C1: Revenue Total ($) | D1: Revenue Weso ($)
A2: Salud y cuidado | B2: 249106 | C2: 12951444 | D2: 4265433
A3: Hogar y Propiedades | B3: 1463404 | C3: 144311473 | D3: 32194139
A4: Veterinario | B4: 1176805 | C4: 103311731 | D4: 22479458
A5: Asistencia en Ruta - Livianos | B5: 4330545 | C5: 395249954 | D5: 87199436

Sheet 1_SEGUROS MONTERREY 🇲🇽
A1: SEGUROS MONTERREY 🇲🇽
A2: Categoría: Salud y cuidado · Servicio: Asistencia Médica Telefónica · País: México
A3: Crecimiento: 0.9% · Churn: 0.6%
A5: Métrica | B5: M1 | C5: M2 | D5: M3 | E5: M4 | F5: M5 | G5: M6 | H5: M7 | I5: M8 | J5: M9 | K5: M10 | L5: M11 | M5: M12 | N5: M13 | O5: M14 | P5: M15 | Q5: M16 | R5: M17 | S5: M18 | T5: M19 | U5: M20 | V5: M21 | W5: M22 | X5: M23 | Y5: M24 | Z5: M25 | AA5: M26 | AB5: M27 | AC5: M28 | AD5: M29 | AE5: M30 | AF5: M31 | AG5: M32 | AH5: M33 | AI5: M34 | AJ5: M35 | AK5: M36 | AL5: M37 | AM5: M38 | AN5: M39 | AO5: M40 | AP5: M41 | AQ5: M42 | AR5: M43 | AS5: M44 | AT5: M45 | AU5: M46 | AV5: M47 | AW5: M48 | AX5: M49 | AY5: M50 | AZ5: M51 | BA5: M52 | BB5: M53 | BC5: M54 | BD5: M55 | BE5: M56 | BF5: M57 | BG5: M58 | BH5: M59 | BI5: M60 | BJ5: M61 | BK5: M62 | BL5: M63 | BM5: M64 | BN5: M65 | BO5: M66 | BP5: M67 | BQ5: M68 | BR5: M69 | BS5: M70 | BT5: M71 | BU5: M72 | BV5: TOTAL
A6: Clientes | B6: 0 | C6: 0 | D6: 0 | E6: 0 | F6: 0 | G6: 0 | H6: 0 | I6: 0 | J6: 150000 | K6: 150442 | L6: 150885 | M6: 151330 | N6: 151775 | O6: 152223 | P6: 152671 | Q6: 153121 | R6: 153572 | S6: 154024 | T6: 154478 | U6: 154933 | V6: 155390 | W6: 155847 | X6: 156306 | Y6: 156767 | Z6: 157229 | AA6: 157692 | AB6: 158157 | AC6: 158622 | AD6: 159090 | AE6: 159558 | AF6: 160029 | AG6: 160500 | AH6: 160973 | AI6: 161447 | AJ6: 161923 | AK6: 162400 | AL6: 162878 | AM6: 163358 | AN6: 163839 | AO6: 164322 | AP6: 164806 | AQ6: 165291 | AR6: 165778 | AS6: 166267 | AT6: 166757 | AU6: 167248 | AV6: 167741 | AW6: 168235 | AX6: 168730 | AY6: 169227 | AZ6: 169726 | BA6: 170226 | BB6: 170728 | BC6: 171230 | BD6: 171735 | BE6: 172241 | BF6: 172748 | BG6: 173257 | BH6: 173768 | BI6: 174280 | BJ6: 174793 | BK6: 175308 | BL6: 175824 | BM6: 176342 | BN6: 176862 | BO6: 177383 | BP6: 177905 | BQ6: 178430 | BR6: 178955 | BS6: 179482 | BT6: 180011 | BU6: 180541
A7: Clientes Perdidos (Churn) | B7: 0 | C7: 0 | D7: 0 | E7: 0 | F7: 0 | G7: 0 | H7: 0 | I7: 0 | J7: 0 | K7: 900 | L7: 903 | M7: 905 | N7: 908 | O7: 911 | P7: 913 | Q7: 916 | R7: 919 | S7: 921 | T7: 924 | U7: 927 | V7: 930 | W7: 932 | X7: 935 | Y7: 938 | Z7: 941 | AA7: 943 | AB7: 946 | AC7: 949 | AD7: 952 | AE7: 955 | AF7: 957 | AG7: 960 | AH7: 963 | AI7: 966 | AJ7: 969 | AK7: 972 | AL7: 974 | AM7: 977 | AN7: 980 | AO7: 983 | AP7: 986 | AQ7: 989 | AR7: 992 | AS7: 995 | AT7: 998 | AU7: 1001 | AV7: 1003 | AW7: 1006 | AX7: 1009 | AY7: 1012 | AZ7: 1015 | BA7: 1018 | BB7: 1021 | BC7: 1024 | BD7: 1027 | BE7: 1030 | BF7: 1033 | BG7: 1036 | BH7: 1040 | BI7: 1043 | BJ7: 1046 | BK7: 1049 | BL7: 1052 | BM7: 1055 | BN7: 1058 | BO7: 1061 | BP7: 1064 | BQ7: 1067 | BR7: 1071 | BS7: 1074 | BT7: 1077 | BU7: 1080 | BV7: 62203
A8: Tasa Uso % | B8: 1 | C8: 1 | D8: 1 | E8: 1 | F8: 1 | G8: 1 | H8: 1 | I8: 1 | J8: 1 | K8: 1 | L8: 1 | M8: 1 | N8: 1 | O8: 1 | P8: 1 | Q8: 1 | R8: 1 | S8: 1 | T8: 1 | U8: 1 | V8: 1 | W8: 1 | X8: 1 | Y8: 1 | Z8: 1 | AA8: 1 | AB8: 1 | AC8: 1 | AD8: 1 | AE8: 1 | AF8: 1 | AG8: 1 | AH8: 1 | AI8: 1 | AJ8: 1 | AK8: 1 | AL8: 1 | AM8: 1 | AN8: 1 | AO8: 1 | AP8: 1 | AQ8: 1 | AR8: 1 | AS8: 1 | AT8: 1 | AU8: 1 | AV8: 1 | AW8: 1 | AX8: 1 | AY8: 1 | AZ8: 1 | BA8: 1 | BB8: 1 | BC8: 1 | BD8: 1 | BE8: 1 | BF8: 1 | BG8: 1 | BH8: 1 | BI8: 1 | BJ8: 1 | BK8: 1 | BL8: 1 | BM8: 1 | BN8: 1 | BO8: 1 | BP8: 1 | BQ8: 1 | BR8: 1 | BS8: 1 | BT8: 1 | BU8: 1
A9: Ticket ($) | B9: 40 | C9: 40 | D9: 40 | E9: 40 | F9: 40 | G9: 40 | H9: 40 | I9: 40 | J9: 40 | K9: 40 | L9: 40 | M9: 40 | N9: 40 | O9: 40 | P9: 40 | Q9: 40 | R9: 40 | S9: 40 | T9: 40 | U9: 40 | V9: 40 | W9: 40 | X9: 40 | Y9: 40 | Z9: 40 | AA9: 40 | AB9: 40 | AC9: 40 | AD9: 40 | AE9: 40 | AF9: 40 | AG9: 40 | AH9: 40 | AI9: 40 | AJ9: 40 | AK9: 40 | AL9: 40 | AM9: 40 | AN9: 40 | AO9: 40 | AP9: 40 | AQ9: 40 | AR9: 40 | AS9: 40 | AT9: 40 | AU9: 40 | AV9: 40 | AW9: 40 | AX9: 40 | AY9: 40 | AZ9: 40 | BA9: 40 | BB9: 40 | BC9: 40 | BD9: 40 | BE9: 40 | BF9: 40 | BG9: 40 | BH9: 40 | BI9: 40 | BJ9: 40 | BK9: 40 | BL9: 40 | BM9: 40 | BN9: 40 | BO9: 40 | BP9: 40 | BQ9: 40 | BR9: 40 | BS9: 40 | BT9: 40 | BU9: 40 | BV9: 40.00
A10: Fee Weso % | B10: 30 | C10: 30 | D10: 30 | E10: 30 | F10: 30 | G10: 30 | H10: 30 | I10: 30 | J10: 30 | K10: 30 | L10: 30 | M10: 30 | N10: 30 | O10: 30 | P10: 30 | Q10: 30 | R10: 30 | S10: 30 | T10: 30 | U10: 30 | V10: 30 | W10: 30 | X10: 30 | Y10: 30 | Z10: 30 | AA10: 30 | AB10: 30 | AC10: 30 | AD10: 30 | AE10: 30 | AF10: 30 | AG10: 30 | AH10: 30 | AI10: 30 | AJ10: 30 | AK10: 30 | AL10: 30 | AM10: 30 | AN10: 30 | AO10: 30 | AP10: 30 | AQ10: 30 | AR10: 30 | AS10: 30 | AT10: 30 | AU10: 30 | AV10: 30 | AW10: 30 | AX10: 30 | AY10: 30 | AZ10: 30 | BA10: 30 | BB10: 30 | BC10: 30 | BD10: 30 | BE10: 30 | BF10: 30 | BG10: 30 | BH10: 30 | BI10: 30 | BJ10: 30 | BK10: 30 | BL10: 30 | BM10: 30 | BN10: 30 | BO10: 30 | BP10: 30 | BQ10: 30 | BR10: 30 | BS10: 30 | BT10: 30 | BU10: 30 | BV10: 30.00
A11: Casos | B11: 0 | C11: 0 | D11: 0 | E11: 0 | F11: 0 | G11: 0 | H11: 0 | I11: 0 | J11: 1500 | K11: 1504 | L11: 1509 | M11: 1513 | N11: 1518 | O11: 1522 | P11: 1527 | Q11: 1531 | R11: 1536 | S11: 1540 | T11: 1545 | U11: 1549 | V11: 1554 | W11: 1558 | X11: 1563 | Y11: 1568 | Z11: 1572 | AA11: 1577 | AB11: 1582 | AC11: 1586 | AD11: 1591 | AE11: 1596 | AF11: 1600 | AG11: 1605 | AH11: 1610 | AI11: 1614 | AJ11: 1619 | AK11: 1624 | AL11: 1629 | AM11: 1634 | AN11: 1638 | AO11: 1643 | AP11: 1648 | AQ11: 1653 | AR11: 1658 | AS11: 1663 | AT11: 1668 | AU11: 1672 | AV11: 1677 | AW11: 1682 | AX11: 1687 | AY11: 1692 | AZ11: 1697 | BA11: 1702 | BB11: 1707 | BC11: 1712 | BD11: 1717 | BE11: 1722 | BF11: 1727 | BG11: 1733 | BH11: 1738 | BI11: 1743 | BJ11: 1748 | BK11: 1753 | BL11: 1758 | BM11: 1763 | BN11: 1769 | BO11: 1774 | BP11: 1779 | BQ11: 1784 | BR11: 1790 | BS11: 1795 | BT11: 1800 | BU11: 1805 | BV11: 105476
A12: Revenue Total ($) | B12: 0 | C12: 0 | D12: 0 | E12: 0 | F12: 0 | G12: 0 | H12: 0 | I12: 0 | J12: 60000 | K12: 60177 | L12: 60354 | M12: 60532 | N12: 60710 | O12: 60889 | P12: 61068 | Q12: 61248 | R12: 61429 | S12: 61610 | T12: 61791 | U12: 61973 | V12: 62156 | W12: 62339 | X12: 62523 | Y12: 62707 | Z12: 62892 | AA12: 63077 | AB12: 63263 | AC12: 63449 | AD12: 63636 | AE12: 63823 | AF12: 64011 | AG12: 64200 | AH12: 64389 | AI12: 64579 | AJ12: 64769 | AK12: 64960 | AL12: 65151 | AM12: 65343 | AN12: 65536 | AO12: 65729 | AP12: 65922 | AQ12: 66117 | AR12: 66311 | AS12: 66507 | AT12: 66703 | AU12: 66899 | AV12: 67096 | AW12: 67294 | AX12: 67492 | AY12: 67691 | AZ12: 67890 | BA12: 68090 | BB12: 68291 | BC12: 68492 | BD12: 68694 | BE12: 68896 | BF12: 69099 | BG12: 69303 | BH12: 69507 | BI12: 69712 | BJ12: 69917 | BK12: 70123 | BL12: 70330 | BM12: 70537 | BN12: 70745 | BO12: 70953 | BP12: 71162 | BQ12: 71372 | BR12: 71582 | BS12: 71793 | BT12: 72004 | BU12: 72217 | BV12: 4219054
A13: Fee Variable Weso ($) | B13: 0 | C13: 0 | D13: 0 | E13: 0 | F13: 0 | G13: 0 | H13: 0 | I13: 0 | J13: 18000 | K13: 18053 | L13: 18106 | M13: 18160 | N13: 18213 | O13: 18267 | P13: 18321 | Q13: 18374 | R13: 18429 | S13: 18483 | T13: 18537 | U13: 18592 | V13: 18647 | W13: 18702 | X13: 18757 | Y13: 18812 | Z13: 18867 | AA13: 18923 | AB13: 18979 | AC13: 19035 | AD13: 19091 | AE13: 19147 | AF13: 19203 | AG13: 19260 | AH13: 19317 | AI13: 19374 | AJ13: 19431 | AK13: 19488 | AL13: 19545 | AM13: 19603 | AN13: 19661 | AO13: 19719 | AP13: 19777 | AQ13: 19835 | AR13: 19893 | AS13: 19952 | AT13: 20011 | AU13: 20070 | AV13: 20129 | AW13: 20188 | AX13: 20248 | AY13: 20307 | AZ13: 20367 | BA13: 20427 | BB13: 20487 | BC13: 20548 | BD13: 20608 | BE13: 20669 | BF13: 20730 | BG13: 20791 | BH13: 20852 | BI13: 20914 | BJ13: 20975 | BK13: 21037 | BL13: 21099 | BM13: 21161 | BN13: 21223 | BO13: 21286 | BP13: 21349 | BQ13: 21412 | BR13: 21475 | BS13: 21538 | BT13: 21601 | BU13: 21665 | BV13: 1265716
A14: Licencia Weso ($) | B14: 0 | C14: 0 | D14: 0 | E14: 0 | F14: 0 | G14: 0 | H14: 0 | I14: 0 | J14: 2000 | K14: 2000 | L14: 2000 | M14: 2000 | N14: 2000 | O14: 2000 | P14: 2000 | Q14: 2000 | R14: 2000 | S14: 2000 | T14: 2000 | U14: 2000 | V14: 2000 | W14: 2000 | X14: 2000 | Y14: 2000 | Z14: 2000 | AA14: 2000 | AB14: 2000 | AC14: 2000 | AD14: 2000 | AE14: 2000 | AF14: 2000 | AG14: 2000 | AH14: 2000 | AI14: 2000 | AJ14: 2000 | AK14: 2000 | AL14: 2000 | AM14: 2000 | AN14: 2000 | AO14: 2000 | AP14: 2000 | AQ14: 2000 | AR14: 2000 | AS14: 2000 | AT14: 2000 | AU14: 2000 | AV14: 2000 | AW14: 2000 | AX14: 2000 | AY14: 2000 | AZ14: 2000 | BA14: 2000 | BB14: 2000 | BC14: 2000 | BD14: 2000 | BE14: 2000 | BF14: 2000 | BG14: 2000 | BH14: 2000 | BI14: 2000 | BJ14: 2000 | BK14: 2000 | BL14: 2000 | BM14: 2000 | BN14: 2000 | BO14: 2000 | BP14: 2000 | BQ14: 2000 | BR14: 2000 | BS14: 2000 | BT14: 2000 | BU14: 2000 | BV14: 128000
A15: Revenue Weso ($) | B15: 0 | C15: 0 | D15: 0 | E15: 0 | F15: 0 | G15: 0 | H15: 0 | I15: 0 | J15: 20000 | K15: 20053 | L15: 20106 | M15: 20160 | N15: 20213 | O15: 20267 | P15: 20321 | Q15: 20374 | R15: 20429 | S15: 20483 | T15: 20537 | U15: 20592 | V15: 20647 | W15: 20702 | X15: 20757 | Y15: 20812 | Z15: 20867 | AA15: 20923 | AB15: 20979 | AC15: 21035 | AD15: 21091 | AE15: 21147 | AF15: 21203 | AG15: 21260 | AH15: 21317 | AI15: 21374 | AJ15: 21431 | AK15: 21488 | AL15: 21545 | AM15: 21603 | AN15: 21661 | AO15: 21719 | AP15: 21777 | AQ15: 21835 | AR15: 21893 | AS15: 21952 | AT15: 22011 | AU15: 22070 | AV15: 22129 | AW15: 22188 | AX15: 22248 | AY15: 22307 | AZ15: 22367 | BA15: 22427 | BB15: 22487 | BC15: 22548 | BD15: 22608 | BE15: 22669 | BF15: 22730 | BG15: 22791 | BH15: 22852 | BI15: 22914 | BJ15: 22975 | BK15: 23037 | BL15: 23099 | BM15: 23161 | BN15: 23223 | BO15: 23286 | BP15: 23349 | BQ15: 23412 | BR15: 23475 | BS15: 23538 | BT15: 23601 | BU15: 23665 | BV15: 1393716
A16: Costos Proveedor ($) | B16: 0 | C16: 0 | D16: 0 | E16: 0 | F16: 0 | G16: 0 | H16: 0 | I16: 0 | J16: 42000 | K16: 42124 | L16: 42248 | M16: 42372 | N16: 42497 | O16: 42622 | P16: 42748 | Q16: 42874 | R16: 43000 | S16: 43127 | T16: 43254 | U16: 43381 | V16: 43509 | W16: 43637 | X16: 43766 | Y16: 43895 | Z16: 44024 | AA16: 44154 | AB16: 44284 | AC16: 44414 | AD16: 44545 | AE16: 44676 | AF16: 44808 | AG16: 44940 | AH16: 45072 | AI16: 45205 | AJ16: 45338 | AK16: 45472 | AL16: 45606 | AM16: 45740 | AN16: 45875 | AO16: 46010 | AP16: 46146 | AQ16: 46282 | AR16: 46418 | AS16: 46555 | AT16: 46692 | AU16: 46829 | AV16: 46967 | AW16: 47106 | AX16: 47245 | AY16: 47384 | AZ16: 47523 | BA16: 47663 | BB16: 47804 | BC16: 47945 | BD16: 48086 | BE16: 48227 | BF16: 48370 | BG16: 48512 | BH16: 48655 | BI16: 48798 | BJ16: 48942 | BK16: 49086 | BL16: 49231 | BM16: 49376 | BN16: 49521 | BO16: 49667 | BP16: 49814 | BQ16: 49960 | BR16: 50107 | BS16: 50255 | BT16: 50403 | BU16: 50552 | BV16: 2953338

Sheet 2_SEGUROS MONTERREY 🇲🇽 - Hog
A1: SEGUROS MONTERREY 🇲🇽 - Hogar
A2: Categoría: Hogar y Propiedades · Servicio: · País: México
A3: Crecimiento: 0.9% · Churn: 0.6%
A5: Métrica | B5: M1 | C5: M2 | D5: M3 | E5: M4 | F5: M5 | G5: M6 | H5: M7 | I5: M8 | J5: M9 | K5: M10 | L5: M11 | M5: M12 | N5: M13 | O5: M14 | P5: M15 | Q5: M16 | R5: M17 | S5: M18 | T5: M19 | U5: M20 | V5: M21 | W5: M22 | X5: M23 | Y5: M24 | Z5: M25 | AA5: M26 | AB5: M27 | AC5: M28 | AD5: M29 | AE5: M30 | AF5: M31 | AG5: M32 | AH5: M33 | AI5: M34 | AJ5: M35 | AK5: M36 | AL5: M37 | AM5: M38 | AN5: M39 | AO5: M40 | AP5: M41 | AQ5: M42 | AR5: M43 | AS5: M44 | AT5: M45 | AU5: M46 | AV5: M47 | AW5: M48 | AX5: M49 | AY5: M50 | AZ5: M51 | BA5: M52 | BB5: M53 | BC5: M54 | BD5: M55 | BE5: M56 | BF5: M57 | BG5: M58 | BH5: M59 | BI5: M60 | BJ5: M61 | BK5: M62 | BL5: M63 | BM5: M64 | BN5: M65 | BO5: M66 | BP5: M67 | BQ5: M68 | BR5: M69 | BS5: M70 | BT5: M71 | BU5: M72 | BV5: TOTAL
A6: Clientes | B6: 0 | C6: 0 | D6: 0 | E6: 0 | F6: 0 | G6: 0 | H6: 0 | I6: 0 | J6: 0 | K6: 0 | L6: 0 | M6: 0 | N6: 30000 | O6: 30088 | P6: 30177 | Q6: 30266 | R6: 30355 | S6: 30445 | T6: 30534 | U6: 30624 | V6: 30714 | W6: 30805 | X6: 30896 | Y6: 30987 | Z6: 31078 | AA6: 31169 | AB6: 31261 | AC6: 31353 | AD6: 31446 | AE6: 31538 | AF6: 31631 | AG6: 31724 | AH6: 31818 | AI6: 31912 | AJ6: 32006 | AK6: 32100 | AL6: 32195 | AM6: 32289 | AN6: 32385 | AO6: 32480 | AP6: 32576 | AQ6: 32672 | AR6: 32768 | AS6: 32864 | AT6: 32961 | AU6: 33058 | AV6: 33156 | AW6: 33253 | AX6: 33351 | AY6: 33450 | AZ6: 33548 | BA6: 33647 | BB6: 33746 | BC6: 33845 | BD6: 33945 | BE6: 34045 | BF6: 34146 | BG6: 34246 | BH6: 34347 | BI6: 34448 | BJ6: 34550 | BK6: 34651 | BL6: 34754 | BM6: 34856 | BN6: 34959 | BO6: 35062 | BP6: 35165 | BQ6: 35268 | BR6: 35372 | BS6: 35477 | BT6: 35581 | BU6: 35686
A7: Clientes Perdidos (Churn) | B7: 0 | C7: 0 | D7: 0 | E7: 0 | F7: 0 | G7: 0 | H7: 0 | I7: 0 | J7: 0 | K7: 0 | L7: 0 | M7: 0 | N7: 0 | O7: 180 | P7: 181 | Q7: 181 | R7: 182 | S7: 182 | T7: 183 | U7: 183 | V7: 184 | W7: 184 | X7: 185 | Y7: 185 | Z7: 186 | AA7: 186 | AB7: 187 | AC7: 188 | AD7: 188 | AE7: 189 | AF7: 189 | AG7: 190 | AH7: 190 | AI7: 191 | AJ7: 191 | AK7: 192 | AL7: 193 | AM7: 193 | AN7: 194 | AO7: 194 | AP7: 195 | AQ7: 195 | AR7: 196 | AS7: 197 | AT7: 197 | AU7: 198 | AV7: 198 | AW7: 199 | AX7: 200 | AY7: 200 | AZ7: 201 | BA7: 201 | BB7: 202 | BC7: 202 | BD7: 203 | BE7: 204 | BF7: 204 | BG7: 205 | BH7: 205 | BI7: 206 | BJ7: 207 | BK7: 207 | BL7: 208 | BM7: 209 | BN7: 209 | BO7: 210 | BP7: 210 | BQ7: 211 | BR7: 212 | BS7: 212 | BT7: 213 | BU7: 213 | BV7: 11580
A8: Tasa Uso % | B8: 1.7 | C8: 1.7 | D8: 1.7 | E8: 1.7 | F8: 1.7 | G8: 1.7 | H8: 1.7 | I8: 1.7 | J8: 1.7 | K8: 1.7 | L8: 1.7 | M8: 1.7 | N8: 1.7 | O8: 1.7 | P8: 1.7 | Q8: 1.7 | R8: 1.7 | S8: 1.7 | T8: 1.7 | U8: 1.7 | V8: 1.7 | W8: 1.7 | X8: 1.7 | Y8: 1.7 | Z8: 1.7 | AA8: 1.7 | AB8: 1.7 | AC8: 1.7 | AD8: 1.7 | AE8: 1.7 | AF8: 1.7 | AG8: 1.7 | AH8: 1.7 | AI8: 1.7 | AJ8: 1.7 | AK8: 1.7 | AL8: 1.7 | AM8: 1.7 | AN8: 1.7 | AO8: 1.7 | AP8: 1.7 | AQ8: 1.7 | AR8: 1.7 | AS8: 1.7 | AT8: 1.7 | AU8: 1.7 | AV8: 1.7 | AW8: 1.7 | AX8: 1.7 | AY8: 1.7 | AZ8: 1.7 | BA8: 1.7 | BB8: 1.7 | BC8: 1.7 | BD8: 1.7 | BE8: 1.7 | BF8: 1.7 | BG8: 1.7 | BH8: 1.7 | BI8: 1.7 | BJ8: 1.7 | BK8: 1.7 | BL8: 1.7 | BM8: 1.7 | BN8: 1.7 | BO8: 1.7 | BP8: 1.7 | BQ8: 1.7 | BR8: 1.7 | BS8: 1.7 | BT8: 1.7 | BU8: 1.7
A9: Ticket ($) | B9: 50 | C9: 50 | D9: 50 | E9: 50 | F9: 50 | G9: 50 | H9: 50 | I9: 50 | J9: 50 | K9: 50 | L9: 50 | M9: 50 | N9: 50 | O9: 50 | P9: 50 | Q9: 50 | R9: 50 | S9: 50 | T9: 50 | U9: 50 | V9: 50 | W9: 50 | X9: 50 | Y9: 50 | Z9: 50 | AA9: 50 | AB9: 50 | AC9: 50 | AD9: 50 | AE9: 50 | AF9: 50 | AG9: 50 | AH9: 50 | AI9: 50 | AJ9: 50 | AK9: 50 | AL9: 50 | AM9: 50 | AN9: 50 | AO9: 50 | AP9: 50 | AQ9: 50 | AR9: 50 | AS9: 50 | AT9: 50 | AU9: 50 | AV9: 50 | AW9: 50 | AX9: 50 | AY9: 50 | AZ9: 50 | BA9: 50 | BB9: 50 | BC9: 50 | BD9: 50 | BE9: 50 | BF9: 50 | BG9: 50 | BH9: 50 | BI9: 50 | BJ9: 50 | BK9: 50 | BL9: 50 | BM9: 50 | BN9: 50 | BO9: 50 | BP9: 50 | BQ9: 50 | BR9: 50 | BS9: 50 | BT9: 50 | BU9: 50 | BV9: 50.00
A10: Fee Weso % | B10: 30 | C10: 30 | D10: 30 | E10: 30 | F10: 30 | G10: 30 | H10: 30 | I10: 30 | J10: 30 | K10: 30 | L10: 30 | M10: 30 | N10: 30 | O10: 30 | P10: 30 | Q10: 30 | R10: 30 | S10: 30 | T10: 30 | U10: 30 | V10: 30 | W10: 30 | X10: 30 | Y10: 30 | Z10: 30 | AA10: 30 | AB10: 30 | AC10: 30 | AD10: 30 | AE10: 30 | AF10: 30 | AG10: 30 | AH10: 30 | AI10: 30 | AJ10: 30 | AK10: 30 | AL10: 30 | AM10: 30 | AN10: 30 | AO10: 30 | AP10: 30 | AQ10: 30 | AR10: 30 | AS10: 30 | AT10: 30 | AU10: 30 | AV10: 30 | AW10: 30 | AX10: 30 | AY10: 30 | AZ10: 30 | BA10: 30 | BB10: 30 | BC10: 30 | BD10: 30 | BE10: 30 | BF10: 30 | BG10: 30 | BH10: 30 | BI10: 30 | BJ10: 30 | BK10: 30 | BL10: 30 | BM10: 30 | BN10: 30 | BO10: 30 | BP10: 30 | BQ10: 30 | BR10: 30 | BS10: 30 | BT10: 30 | BU10: 30 | BV10: 30.00
A11: Casos | B11: 0 | C11: 0 | D11: 0 | E11: 0 | F11: 0 | G11: 0 | H11: 0 | I11: 0 | J11: 0 | K11: 0 | L11: 0 | M11: 0 | N11: 510 | O11: 512 | P11: 513 | Q11: 515 | R11: 516 | S11: 518 | T11: 519 | U11: 521 | V11: 522 | W11: 524 | X11: 525 | Y11: 527 | Z11: 528 | AA11: 530 | AB11: 531 | AC11: 533 | AD11: 535 | AE11: 536 | AF11: 538 | AG11: 539 | AH11: 541 | AI11: 542 | AJ11: 544 | AK11: 546 | AL11: 547 | AM11: 549 | AN11: 551 | AO11: 552 | AP11: 554 | AQ11: 555 | AR11: 557 | AS11: 559 | AT11: 560 | AU11: 562 | AV11: 564 | AW11: 565 | AX11: 567 | AY11: 569 | AZ11: 570 | BA11: 572 | BB11: 574 | BC11: 575 | BD11: 577 | BE11: 579 | BF11: 580 | BG11: 582 | BH11: 584 | BI11: 586 | BJ11: 587 | BK11: 589 | BL11: 591 | BM11: 593 | BN11: 594 | BO11: 596 | BP11: 598 | BQ11: 600 | BR11: 601 | BS11: 603 | BT11: 605 | BU11: 607 | BV11: 33417
A12: Revenue Total ($) | B12: 0 | C12: 0 | D12: 0 | E12: 0 | F12: 0 | G12: 0 | H12: 0 | I12: 0 | J12: 0 | K12: 0 | L12: 0 | M12: 0 | N12: 25500 | O12: 25575 | P12: 25650 | Q12: 25726 | R12: 25802 | S12: 25878 | T12: 25954 | U12: 26031 | V12: 26107 | W12: 26184 | X12: 26261 | Y12: 26339 | Z12: 26416 | AA12: 26494 | AB12: 26572 | AC12: 26650 | AD12: 26729 | AE12: 26808 | AF12: 26887 | AG12: 26966 | AH12: 27045 | AI12: 27125 | AJ12: 27205 | AK12: 27285 | AL12: 27365 | AM12: 27446 | AN12: 27527 | AO12: 27608 | AP12: 27689 | AQ12: 27771 | AR12: 27853 | AS12: 27935 | AT12: 28017 | AU12: 28100 | AV12: 28182 | AW12: 28265 | AX12: 28349 | AY12: 28432 | AZ12: 28516 | BA12: 28600 | BB12: 28684 | BC12: 28769 | BD12: 28853 | BE12: 28938 | BF12: 29024 | BG12: 29109 | BH12: 29195 | BI12: 29281 | BJ12: 29367 | BK12: 29454 | BL12: 29540 | BM12: 29628 | BN12: 29715 | BO12: 29802 | BP12: 29890 | BQ12: 29978 | BR12: 30067 | BS12: 30155 | BT12: 30244 | BU12: 30333 | BV12: 1670870
A13: Fee Variable Weso ($) | B13: 0 | C13: 0 | D13: 0 | E13: 0 | F13: 0 | G13: 0 | H13: 0 | I13: 0 | J13: 0 | K13: 0 | L13: 0 | M13: 0 | N13: 7650 | O13: 7673 | P13: 7695 | Q13: 7718 | R13: 7741 | S13: 7763 | T13: 7786 | U13: 7809 | V13: 7832 | W13: 7855 | X13: 7878 | Y13: 7902 | Z13: 7925 | AA13: 7948 | AB13: 7972 | AC13: 7995 | AD13: 8019 | AE13: 8042 | AF13: 8066 | AG13: 8090 | AH13: 8114 | AI13: 8137 | AJ13: 8161 | AK13: 8185 | AL13: 8210 | AM13: 8234 | AN13: 8258 | AO13: 8282 | AP13: 8307 | AQ13: 8331 | AR13: 8356 | AS13: 8380 | AT13: 8405 | AU13: 8430 | AV13: 8455 | AW13: 8480 | AX13: 8505 | AY13: 8530 | AZ13: 8555 | BA13: 8580 | BB13: 8605 | BC13: 8631 | BD13: 8656 | BE13: 8682 | BF13: 8707 | BG13: 8733 | BH13: 8758 | BI13: 8784 | BJ13: 8810 | BK13: 8836 | BL13: 8862 | BM13: 8888 | BN13: 8914 | BO13: 8941 | BP13: 8967 | BQ13: 8993 | BR13: 9020 | BS13: 9047 | BT13: 9073 | BU13: 9100 | BV13: 501261
A14: Licencia Weso ($) | B14: 0 | C14: 0 | D14: 0 | E14: 0 | F14: 0 | G14: 0 | H14: 0 | I14: 0 | J14: 0 | K14: 0 | L14: 0 | M14: 0 | N14: 0 | O14: 0 | P14: 0 | Q14: 0 | R14: 0 | S14: 0 | T14: 0 | U14: 0 | V14: 0 | W14: 0 | X14: 0 | Y14: 0 | Z14: 0 | AA14: 0 | AB14: 0 | AC14: 0 | AD14: 0 | AE14: 0 | AF14: 0 | AG14: 0 | AH14: 0 | AI14: 0 | AJ14: 0 | AK14: 0 | AL14: 0 | AM14: 0 | AN14: 0 | AO14: 0 | AP14: 0 | AQ14: 0 | AR14: 0 | AS14: 0 | AT14: 0 | AU14: 0 | AV14: 0 | AW14: 0 | AX14: 0 | AY14: 0 | AZ14: 0 | BA14: 0 | BB14: 0 | BC14: 0 | BD14: 0 | BE14: 0 | BF14: 0 | BG14: 0 | BH14: 0 | BI14: 0 | BJ14: 0 | BK14: 0 | BL14: 0 | BM14: 0 | BN14: 0 | BO14: 0 | BP14: 0 | BQ14: 0 | BR14: 0 | BS14: 0 | BT14: 0 | BU14: 0 | BV14: 0
A15: Revenue Weso ($) | B15: 0 | C15: 0 | D15: 0 | E15: 0 | F15: 0 | G15: 0 | H15: 0 | I15: 0 | J15: 0 | K15: 0 | L15: 0 | M15: 0 | N15: 7650 | O15: 7673 | P15: 7695 | Q15: 7718 | R15: 7741 | S15: 7763 | T15: 7786 | U15: 7809 | V15: 7832 | W15: 7855 | X15: 7878 | Y15: 7902 | Z15: 7925 | AA15: 7948 | AB15: 7972 | AC15: 7995 | AD15: 8019 | AE15: 8042 | AF15: 8066 | AG15: 8090 | AH15: 8114 | AI15: 8137 | AJ15: 8161 | AK15: 8185 | AL15: 8210 | AM15: 8234 | AN15: 8258 | AO15: 8282 | AP15: 8307 | AQ15: 8331 | AR15: 8356 | AS15: 8380 | AT15: 8405 | AU15: 8430 | AV15: 8455 | AW15: 8480 | AX15: 8505 | AY15: 8530 | AZ15: 8555 | BA15: 8580 | BB15: 8605 | BC15: 8631 | BD15: 8656 | BE15: 8682 | BF15: 8707 | BG15: 8733 | BH15: 8758 | BI15: 8784 | BJ15: 8810 | BK15: 8836 | BL15: 8862 | BM15: 8888 | BN15: 8914 | BO15: 8941 | BP15: 8967 | BQ15: 8993 | BR15: 9020 | BS15: 9047 | BT15: 9073 | BU15: 9100 | BV15: 501261
A16: Costos Proveedor ($) | B16: 0 | C16: 0 | D16: 0 | E16: 0 | F16: 0 | G16: 0 | H16: 0 | I16: 0 | J16: 0 | K16: 0 | L16: 0 | M16: 0 | N16: 17850 | O16: 17903 | P16: 17955 | Q16: 18008 | R16: 18061 | S16: 18114 | T16: 18168 | U16: 18221 | V16: 18275 | W16: 18329 | X16: 18383 | Y16: 18437 | Z16: 18491 | AA16: 18546 | AB16: 18600 | AC16: 18655 | AD16: 18710 | AE16: 18765 | AF16: 18821 | AG16: 18876 | AH16: 18932 | AI16: 18987 | AJ16: 19043 | AK16: 19099 | AL16: 19156 | AM16: 19212 | AN16: 19269 | AO16: 19326 | AP16: 19382 | AQ16: 19440 | AR16: 19497 | AS16: 19554 | AT16: 19612 | AU16: 19670 | AV16: 19728 | AW16: 19786 | AX16: 19844 | AY16: 19902 | AZ16: 19961 | BA16: 20020 | BB16: 20079 | BC16: 20138 | BD16: 20197 | BE16: 20257 | BF16: 20317 | BG16: 20376 | BH16: 20436 | BI16: 20497 | BJ16: 20557 | BK16: 20618 | BL16: 20678 | BM16: 20739 | BN16: 20800 | BO16: 20862 | BP16: 20923 | BQ16: 20985 | BR16: 21047 | BS16: 21109 | BT16: 21171 | BU16: 21233 | BV16: 1169609

Sheet 3_CHUBB
A1: CHUBB
A2: Categoría: Veterinario · Servicio: · País: Estados Unidos
A3: Crecimiento: 1.2% · Churn: 0.7%
A5: Métrica | B5: M1 | C5: M2 | D5: M3 | E5: M4 | F5: M5 | G5: M6 | H5: M7 | I5: M8 | J5: M9 | K5: M10 | L5: M11 | M5: M12 | N5: M13 | O5: M14 | P5: M15 | Q5: M16 | R5: M17 | S5: M18 | T5: M19 | U5: M20 | V5: M21 | W5: M22 | X5: M23 | Y5: M24 | Z5: M25 | AA5: M26 | AB5: M27 | AC5: M28 | AD5: M29 | AE5: M30 | AF5: M31 | AG5: M32 | AH5: M33 | AI5: M34 | AJ5: M35 | AK5: M36 | AL5: M37 | AM5: M38 | AN5: M39 | AO5: M40 | AP5: M41 | AQ5: M42 | AR5: M43 | AS5: M44 | AT5: M45 | AU5: M46 | AV5: M47 | AW5: M48 | AX5: M49 | AY5: M50 | AZ5: M51 | BA5: M52 | BB5: M53 | BC5: M54 | BD5: M55 | BE5: M56 | BF5: M57 | BG5: M58 | BH5: M59 | BI5: M60 | BJ5: M61 | BK5: M62 | BL5: M63 | BM5: M64 | BN5: M65 | BO5: M66 | BP5: M67 | BQ5: M68 | BR5: M69 | BS5: M70 | BT5: M71 | BU5: M72 | BV5: TOTAL
A6: Clientes | B6: 0 | C6: 0 | D6: 0 | E6: 0 | F6: 0 | G6: 0 | H6: 0 | I6: 0 | J6: 550000 | K6: 552704 | L6: 555421 | M6: 558151 | N6: 560895 | O6: 563653 | P6: 566423 | Q6: 569208 | R6: 572006 | S6: 574818 | T6: 577644 | U6: 580484 | V6: 583337 | W6: 586205 | X6: 589087 | Y6: 591983 | Z6: 594893 | AA6: 597818 | AB6: 600756 | AC6: 603710 | AD6: 606678 | AE6: 609660 | AF6: 612657 | AG6: 615669 | AH6: 618695 | AI6: 621737 | AJ6: 624793 | AK6: 627865 | AL6: 630952 | AM6: 634053 | AN6: 637170 | AO6: 640303 | AP6: 643450 | AQ6: 646614 | AR6: 649792 | AS6: 652987 | AT6: 656197 | AU6: 659423 | AV6: 662664 | AW6: 665922 | AX6: 669196 | AY6: 672485 | AZ6: 675791 | BA6: 679114 | BB6: 682452 | BC6: 685807 | BD6: 689178 | BE6: 692566 | BF6: 695971 | BG6: 699393 | BH6: 702831 | BI6: 706286 | BJ6: 709758 | BK6: 713247 | BL6: 716753 | BM6: 720277 | BN6: 723818 | BO6: 727376 | BP6: 730952 | BQ6: 734545 | BR6: 738156 | BS6: 741785 | BT6: 745432 | BU6: 749096
A7: Clientes Perdidos (Churn) | B7: 0 | C7: 0 | D7: 0 | E7: 0 | F7: 0 | G7: 0 | H7: 0 | I7: 0 | J7: 0 | K7: 3850 | L7: 3869 | M7: 3888 | N7: 3907 | O7: 3926 | P7: 3946 | Q7: 3965 | R7: 3984 | S7: 4004 | T7: 4024 | U7: 4044 | V7: 4063 | W7: 4083 | X7: 4103 | Y7: 4124 | Z7: 4144 | AA7: 4164 | AB7: 4185 | AC7: 4205 | AD7: 4226 | AE7: 4247 | AF7: 4268 | AG7: 4289 | AH7: 4310 | AI7: 4331 | AJ7: 4352 | AK7: 4374 | AL7: 4395 | AM7: 4417 | AN7: 4438 | AO7: 4460 | AP7: 4482 | AQ7: 4504 | AR7: 4526 | AS7: 4549 | AT7: 4571 | AU7: 4593 | AV7: 4616 | AW7: 4639 | AX7: 4661 | AY7: 4684 | AZ7: 4707 | BA7: 4731 | BB7: 4754 | BC7: 4777 | BD7: 4801 | BE7: 4824 | BF7: 4848 | BG7: 4872 | BH7: 4896 | BI7: 4920 | BJ7: 4944 | BK7: 4968 | BL7: 4993 | BM7: 5017 | BN7: 5042 | BO7: 5067 | BP7: 5092 | BQ7: 5117 | BR7: 5142 | BS7: 5167 | BT7: 5192 | BU7: 5218 | BV7: 283498
A8: Tasa Uso % | B8: 1.2 | C8: 1.2 | D8: 1.2 | E8: 1.2 | F8: 1.2 | G8: 1.2 | H8: 1.2 | I8: 1.2 | J8: 1.2 | K8: 1.2 | L8: 1.2 | M8: 1.2 | N8: 1.2 | O8: 1.2 | P8: 1.2 | Q8: 1.2 | R8: 1.2 | S8: 1.2 | T8: 1.2 | U8: 1.2 | V8: 1.2 | W8: 1.2 | X8: 1.2 | Y8: 1.2 | Z8: 1.2 | AA8: 1.2 | AB8: 1.2 | AC8: 1.2 | AD8: 1.2 | AE8: 1.2 | AF8: 1.2 | AG8: 1.2 | AH8: 1.2 | AI8: 1.2 | AJ8: 1.2 | AK8: 1.2 | AL8: 1.2 | AM8: 1.2 | AN8: 1.2 | AO8: 1.2 | AP8: 1.2 | AQ8: 1.2 | AR8: 1.2 | AS8: 1.2 | AT8: 1.2 | AU8: 1.2 | AV8: 1.2 | AW8: 1.2 | AX8: 1.2 | AY8: 1.2 | AZ8: 1.2 | BA8: 1.2 | BB8: 1.2 | BC8: 1.2 | BD8: 1.2 | BE8: 1.2 | BF8: 1.2 | BG8: 1.2 | BH8: 1.2 | BI8: 1.2 | BJ8: 1.2 | BK8: 1.2 | BL8: 1.2 | BM8: 1.2 | BN8: 1.2 | BO8: 1.2 | BP8: 1.2 | BQ8: 1.2 | BR8: 1.2 | BS8: 1.2 | BT8: 1.2 | BU8: 1.2
A9: Ticket ($) | B9: 110 | C9: 110 | D9: 110 | E9: 110 | F9: 110 | G9: 110 | H9: 110 | I9: 110 | J9: 110 | K9: 110 | L9: 110 | M9: 110 | N9: 110 | O9: 110 | P9: 110 | Q9: 110 | R9: 110 | S9: 110 | T9: 110 | U9: 110 | V9: 110 | W9: 110 | X9: 110 | Y9: 110 | Z9: 110 | AA9: 110 | AB9: 110 | AC9: 110 | AD9: 110 | AE9: 110 | AF9: 110 | AG9: 110 | AH9: 110 | AI9: 110 | AJ9: 110 | AK9: 110 | AL9: 110 | AM9: 110 | AN9: 110 | AO9: 110 | AP9: 110 | AQ9: 110 | AR9: 110 | AS9: 110 | AT9: 110 | AU9: 110 | AV9: 110 | AW9: 110 | AX9: 110 | AY9: 110 | AZ9: 110 | BA9: 110 | BB9: 110 | BC9: 110 | BD9: 110 | BE9: 110 | BF9: 110 | BG9: 110 | BH9: 110 | BI9: 110 | BJ9: 110 | BK9: 110 | BL9: 110 | BM9: 110 | BN9: 110 | BO9: 110 | BP9: 110 | BQ9: 110 | BR9: 110 | BS9: 110 | BT9: 110 | BU9: 110 | BV9: 110.00
A10: Fee Weso % | B10: 20 | C10: 20 | D10: 20 | E10: 20 | F10: 20 | G10: 20 | H10: 20 | I10: 20 | J10: 20 | K10: 20 | L10: 20 | M10: 20 | N10: 20 | O10: 20 | P10: 20 | Q10: 20 | R10: 20 | S10: 20 | T10: 20 | U10: 20 | V10: 20 | W10: 20 | X10: 20 | Y10: 20 | Z10: 20 | AA10: 20 | AB10: 20 | AC10: 20 | AD10: 20 | AE10: 20 | AF10: 20 | AG10: 20 | AH10: 20 | AI10: 20 | AJ10: 20 | AK10: 20 | AL10: 20 | AM10: 20 | AN10: 20 | AO10: 20 | AP10: 20 | AQ10: 20 | AR10: 20 | AS10: 20 | AT10: 20 | AU10: 20 | AV10: 20 | AW10: 20 | AX10: 20 | AY10: 20 | AZ10: 20 | BA10: 20 | BB10: 20 | BC10: 20 | BD10: 20 | BE10: 20 | BF10: 20 | BG10: 20 | BH10: 20 | BI10: 20 | BJ10: 20 | BK10: 20 | BL10: 20 | BM10: 20 | BN10: 20 | BO10: 20 | BP10: 20 | BQ10: 20 | BR10: 20 | BS10: 20 | BT10: 20 | BU10: 20 | BV10: 20.00
A11: Casos | B11: 0 | C11: 0 | D11: 0 | E11: 0 | F11: 0 | G11: 0 | H11: 0 | I11: 0 | J11: 6600 | K11: 6632 | L11: 6665 | M11: 6698 | N11: 6731 | O11: 6764 | P11: 6797 | Q11: 6830 | R11: 6864 | S11: 6898 | T11: 6932 | U11: 6966 | V11: 7000 | W11: 7034 | X11: 7069 | Y11: 7104 | Z11: 7139 | AA11: 7174 | AB11: 7209 | AC11: 7245 | AD11: 7280 | AE11: 7316 | AF11: 7352 | AG11: 7388 | AH11: 7424 | AI11: 7461 | AJ11: 7498 | AK11: 7534 | AL11: 7571 | AM11: 7609 | AN11: 7646 | AO11: 7684 | AP11: 7721 | AQ11: 7759 | AR11: 7798 | AS11: 7836 | AT11: 7874 | AU11: 7913 | AV11: 7952 | AW11: 7991 | AX11: 8030 | AY11: 8070 | AZ11: 8109 | BA11: 8149 | BB11: 8189 | BC11: 8230 | BD11: 8270 | BE11: 8311 | BF11: 8352 | BG11: 8393 | BH11: 8434 | BI11: 8475 | BJ11: 8517 | BK11: 8559 | BL11: 8601 | BM11: 8643 | BN11: 8686 | BO11: 8729 | BP11: 8771 | BQ11: 8815 | BR11: 8858 | BS11: 8901 | BT11: 8945 | BU11: 8989 | BV11: 494985
A12: Revenue Total ($) | B12: 0 | C12: 0 | D12: 0 | E12: 0 | F12: 0 | G12: 0 | H12: 0 | I12: 0 | J12: 726000 | K12: 729569 | L12: 733156 | M12: 736760 | N12: 740382 | O12: 744021 | P12: 747679 | Q12: 751355 | R12: 755048 | S12: 758760 | T12: 762490 | U12: 766239 | V12: 770005 | W12: 773791 | X12: 777595 | Y12: 781417 | Z12: 785259 | AA12: 789119 | AB12: 792998 | AC12: 796897 | AD12: 800814 | AE12: 804751 | AF12: 808707 | AG12: 812683 | AH12: 816678 | AI12: 820693 | AJ12: 824727 | AK12: 828782 | AL12: 832856 | AM12: 836950 | AN12: 841065 | AO12: 845199 | AP12: 849354 | AQ12: 853530 | AR12: 857726 | AS12: 861942 | AT12: 866180 | AU12: 870438 | AV12: 874717 | AW12: 879017 | AX12: 883338 | AY12: 887681 | AZ12: 892045 | BA12: 896430 | BB12: 900837 | BC12: 905265 | BD12: 909716 | BE12: 914188 | BF12: 918682 | BG12: 923198 | BH12: 927737 | BI12: 932297 | BJ12: 936880 | BK12: 941486 | BL12: 946115 | BM12: 950766 | BN12: 955440 | BO12: 960137 | BP12: 964857 | BQ12: 969600 | BR12: 974366 | BS12: 979156 | BT12: 983970 | BU12: 988807 | BV12: 54448342
A13: Fee Variable Weso ($) | B13: 0 | C13: 0 | D13: 0 | E13: 0 | F13: 0 | G13: 0 | H13: 0 | I13: 0 | J13: 145200 | K13: 145914 | L13: 146631 | M13: 147352 | N13: 148076 | O13: 148804 | P13: 149536 | Q13: 150271 | R13: 151010 | S13: 151752 | T13: 152498 | U13: 153248 | V13: 154001 | W13: 154758 | X13: 155519 | Y13: 156283 | Z13: 157052 | AA13: 157824 | AB13: 158600 | AC13: 159379 | AD13: 160163 | AE13: 160950 | AF13: 161741 | AG13: 162537 | AH13: 163336 | AI13: 164139 | AJ13: 164945 | AK13: 165756 | AL13: 166571 | AM13: 167390 | AN13: 168213 | AO13: 169040 | AP13: 169871 | AQ13: 170706 | AR13: 171545 | AS13: 172388 | AT13: 173236 | AU13: 174088 | AV13: 174943 | AW13: 175803 | AX13: 176668 | AY13: 177536 | AZ13: 178409 | BA13: 179286 | BB13: 180167 | BC13: 181053 | BD13: 181943 | BE13: 182838 | BF13: 183736 | BG13: 184640 | BH13: 185547 | BI13: 186459 | BJ13: 187376 | BK13: 188297 | BL13: 189223 | BM13: 190153 | BN13: 191088 | BO13: 192027 | BP13: 192971 | BQ13: 193920 | BR13: 194873 | BS13: 195831 | BT13: 196794 | BU13: 197761 | BV13: 10889668
A14: Licencia Weso ($) | B14: 0 | C14: 0 | D14: 0 | E14: 0 | F14: 0 | G14: 0 | H14: 0 | I14: 0 | J14: 2000 | K14: 2000 | L14: 2000 | M14: 2000 | N14: 2000 | O14: 2000 | P14: 2000 | Q14: 2000 | R14: 2000 | S14: 2000 | T14: 2000 | U14: 2000 | V14: 2000 | W14: 2000 | X14: 2000 | Y14: 2000 | Z14: 2000 | AA14: 2000 | AB14: 2000 | AC14: 2000 | AD14: 2000 | AE14: 2000 | AF14: 2000 | AG14: 2000 | AH14: 2000 | AI14: 2000 | AJ14: 2000 | AK14: 2000 | AL14: 2000 | AM14: 2000 | AN14: 2000 | AO14: 2000 | AP14: 2000 | AQ14: 2000 | AR14: 2000 | AS14: 2000 | AT14: 2000 | AU14: 2000 | AV14: 2000 | AW14: 2000 | AX14: 2000 | AY14: 2000 | AZ14: 2000 | BA14: 2000 | BB14: 2000 | BC14: 2000 | BD14: 2000 | BE14: 2000 | BF14: 2000 | BG14: 2000 | BH14: 2000 | BI14: 2000 | BJ14: 2000 | BK14: 2000 | BL14: 2000 | BM14: 2000 | BN14: 2000 | BO14: 2000 | BP14: 2000 | BQ14: 2000 | BR14: 2000 | BS14: 2000 | BT14: 2000 | BU14: 2000 | BV14: 128000
A15: Revenue Weso ($) | B15: 0 | C15: 0 | D15: 0 | E15: 0 | F15: 0 | G15: 0 | H15: 0 | I15: 0 | J15: 147200 | K15: 147914 | L15: 148631 | M15: 149352 | N15: 150076 | O15: 150804 | P15: 151536 | Q15: 152271 | R15: 153010 | S15: 153752 | T15: 154498 | U15: 155248 | V15: 156001 | W15: 156758 | X15: 157519 | Y15: 158283 | Z15: 159052 | AA15: 159824 | AB15: 160600 | AC15: 161379 | AD15: 162163 | AE15: 162950 | AF15: 163741 | AG15: 164537 | AH15: 165336 | AI15: 166139 | AJ15: 166945 | AK15: 167756 | AL15: 168571 | AM15: 169390 | AN15: 170213 | AO15: 171040 | AP15: 171871 | AQ15: 172706 | AR15: 173545 | AS15: 174388 | AT15: 175236 | AU15: 176088 | AV15: 176943 | AW15: 177803 | AX15: 178668 | AY15: 179536 | AZ15: 180409 | BA15: 181286 | BB15: 182167 | BC15: 183053 | BD15: 183943 | BE15: 184838 | BF15: 185736 | BG15: 186640 | BH15: 187547 | BI15: 188459 | BJ15: 189376 | BK15: 190297 | BL15: 191223 | BM15: 192153 | BN15: 193088 | BO15: 194027 | BP15: 194971 | BQ15: 195920 | BR15: 196873 | BS15: 197831 | BT15: 198794 | BU15: 199761 | BV15: 11017668
A16: Costos Proveedor ($) | B16: 0 | C16: 0 | D16: 0 | E16: 0 | F16: 0 | G16: 0 | H16: 0 | I16: 0 | J16: 580800 | K16: 583655 | L16: 586524 | M16: 589408 | N16: 592305 | O16: 595217 | P16: 598143 | Q16: 601084 | R16: 604039 | S16: 607008 | T16: 609992 | U16: 612991 | V16: 616004 | W16: 619033 | X16: 622076 | Y16: 625134 | Z16: 628207 | AA16: 631295 | AB16: 634399 | AC16: 637517 | AD16: 640651 | AE16: 643801 | AF16: 646966 | AG16: 650146 | AH16: 653342 | AI16: 656554 | AJ16: 659782 | AK16: 663025 | AL16: 666285 | AM16: 669560 | AN16: 672852 | AO16: 676160 | AP16: 679484 | AQ16: 682824 | AR16: 686181 | AS16: 689554 | AT16: 692944 | AU16: 696350 | AV16: 699774 | AW16: 703214 | AX16: 706671 | AY16: 710145 | AZ16: 713636 | BA16: 717144 | BB16: 720669 | BC16: 724212 | BD16: 727772 | BE16: 731350 | BF16: 734946 | BG16: 738558 | BH16: 742189 | BI16: 745838 | BJ16: 749504 | BK16: 753189 | BL16: 756892 | BM16: 760613 | BN16: 764352 | BO16: 768109 | BP16: 771885 | BQ16: 775680 | BR16: 779493 | BS16: 783325 | BT16: 787176 | BU16: 791046 | BV16: 43558673

Sheet 4_CHUBB - Hogar Singapur
A1: CHUBB - Hogar Singapur
A2: Categoría: Hogar y Propiedades · Servicio: · País: Singapur
A3: Crecimiento: 0.8% · Churn: 0.6%
A5: Métrica | B5: M1 | C5: M2 | D5: M3 | E5: M4 | F5: M5 | G5: M6 | H5: M7 | I5: M8 | J5: M9 | K5: M10 | L5: M11 | M5: M12 | N5: M13 | O5: M14 | P5: M15 | Q5: M16 | R5: M17 | S5: M18 | T5: M19 | U5: M20 | V5: M21 | W5: M22 | X5: M23 | Y5: M24 | Z5: M25 | AA5: M26 | AB5: M27 | AC5: M28 | AD5: M29 | AE5: M30 | AF5: M31 | AG5: M32 | AH5: M33 | AI5: M34 | AJ5: M35 | AK5: M36 | AL5: M37 | AM5: M38 | AN5: M39 | AO5: M40 | AP5: M41 | AQ5: M42 | AR5: M43 | AS5: M44 | AT5: M45 | AU5: M46 | AV5: M47 | AW5: M48 | AX5: M49 | AY5: M50 | AZ5: M51 | BA5: M52 | BB5: M53 | BC5: M54 | BD5: M55 | BE5: M56 | BF5: M57 | BG5: M58 | BH5: M59 | BI5: M60 | BJ5: M61 | BK5: M62 | BL5: M63 | BM5: M64 | BN5: M65 | BO5: M66 | BP5: M67 | BQ5: M68 | BR5: M69 | BS5: M70 | BT5: M71 | BU5: M72 | BV5: TOTAL
A6: Clientes | B6: 0 | C6: 0 | D6: 0 | E6: 0 | F6: 0 | G6: 0 | H6: 0 | I6: 25000 | J6: 25049 | K6: 25098 | L6: 25147 | M6: 25196 | N6: 25245 | O6: 25294 | P6: 25344 | Q6: 25393 | R6: 25443 | S6: 25492 | T6: 25542 | U6: 25592 | V6: 25642 | W6: 25692 | X6: 25742 | Y6: 25792 | Z6: 25843 | AA6: 25893 | AB6: 25944 | AC6: 25994 | AD6: 26045 | AE6: 26096 | AF6: 26147 | AG6: 26198 | AH6: 26249 | AI6: 26300 | AJ6: 26352 | AK6: 26403 | AL6: 26455 | AM6: 26506 | AN6: 26558 | AO6: 26610 | AP6: 26662 | AQ6: 26714 | AR6: 26766 | AS6: 26818 | AT6: 26871 | AU6: 26923 | AV6: 26976 | AW6: 27028 | AX6: 27081 | AY6: 27134 | AZ6: 27187 | BA6: 27240 | BB6: 27293 | BC6: 27346 | BD6: 27400 | BE6: 27453 | BF6: 27507 | BG6: 27560 | BH6: 27614 | BI6: 27668 | BJ6: 27722 | BK6: 27776 | BL6: 27830 | BM6: 27885 | BN6: 27939 | BO6: 27994 | BP6: 28048 | BQ6: 28103 | BR6: 28158 | BS6: 28213 | BT6: 28268 | BU6: 28323
A7: Clientes Perdidos (Churn) | B7: 0 | C7: 0 | D7: 0 | E7: 0 | F7: 0 | G7: 0 | H7: 0 | I7: 0 | J7: 150 | K7: 150 | L7: 151 | M7: 151 | N7: 151 | O7: 151 | P7: 152 | Q7: 152 | R7: 152 | S7: 153 | T7: 153 | U7: 153 | V7: 154 | W7: 154 | X7: 154 | Y7: 154 | Z7: 155 | AA7: 155 | AB7: 155 | AC7: 156 | AD7: 156 | AE7: 156 | AF7: 157 | AG7: 157 | AH7: 157 | AI7: 157 | AJ7: 158 | AK7: 158 | AL7: 158 | AM7: 159 | AN7: 159 | AO7: 159 | AP7: 160 | AQ7: 160 | AR7: 160 | AS7: 161 | AT7: 161 | AU7: 161 | AV7: 162 | AW7: 162 | AX7: 162 | AY7: 162 | AZ7: 163 | BA7: 163 | BB7: 163 | BC7: 164 | BD7: 164 | BE7: 164 | BF7: 165 | BG7: 165 | BH7: 165 | BI7: 166 | BJ7: 166 | BK7: 166 | BL7: 167 | BM7: 167 | BN7: 167 | BO7: 168 | BP7: 168 | BQ7: 168 | BR7: 169 | BS7: 169 | BT7: 169 | BU7: 170 | BV7: 10215
A8: Tasa Uso % | B8: 1.2 | C8: 1.2 | D8: 1.2 | E8: 1.2 | F8: 1.2 | G8: 1.2 | H8: 1.2 | I8: 1.2 | J8: 1.2 | K8: 1.2 | L8: 1.2 | M8: 1.2 | N8: 1.2 | O8: 1.2 | P8: 1.2 | Q8: 1.2 | R8: 1.2 | S8: 1.2 | T8: 1.2 | U8: 1.2 | V8: 1.2 | W8: 1.2 | X8: 1.2 | Y8: 1.2 | Z8: 1.2 | AA8: 1.2 | AB8: 1.2 | AC8: 1.2 | AD8: 1.2 | AE8: 1.2 | AF8: 1.2 | AG8: 1.2 | AH8: 1.2 | AI8: 1.2 | AJ8: 1.2 | AK8: 1.2 | AL8: 1.2 | AM8: 1.2 | AN8: 1.2 | AO8: 1.2 | AP8: 1.2 | AQ8: 1.2 | AR8: 1.2 | AS8: 1.2 | AT8: 1.2 | AU8: 1.2 | AV8: 1.2 | AW8: 1.2 | AX8: 1.2 | AY8: 1.2 | AZ8: 1.2 | BA8: 1.2 | BB8: 1.2 | BC8: 1.2 | BD8: 1.2 | BE8: 1.2 | BF8: 1.2 | BG8: 1.2 | BH8: 1.2 | BI8: 1.2 | BJ8: 1.2 | BK8: 1.2 | BL8: 1.2 | BM8: 1.2 | BN8: 1.2 | BO8: 1.2 | BP8: 1.2 | BQ8: 1.2 | BR8: 1.2 | BS8: 1.2 | BT8: 1.2 | BU8: 1.2
A9: Ticket ($) | B9: 70 | C9: 70 | D9: 70 | E9: 70 | F9: 70 | G9: 70 | H9: 70 | I9: 70 | J9: 70 | K9: 70 | L9: 70 | M9: 70 | N9: 70 | O9: 70 | P9: 70 | Q9: 70 | R9: 70 | S9: 70 | T9: 70 | U9: 70 | V9: 70 | W9: 70 | X9: 70 | Y9: 70 | Z9: 70 | AA9: 70 | AB9: 70 | AC9: 70 | AD9: 70 | AE9: 70 | AF9: 70 | AG9: 70 | AH9: 70 | AI9: 70 | AJ9: 70 | AK9: 70 | AL9: 70 | AM9: 70 | AN9: 70 | AO9: 70 | AP9: 70 | AQ9: 70 | AR9: 70 | AS9: 70 | AT9: 70 | AU9: 70 | AV9: 70 | AW9: 70 | AX9: 70 | AY9: 70 | AZ9: 70 | BA9: 70 | BB9: 70 | BC9: 70 | BD9: 70 | BE9: 70 | BF9: 70 | BG9: 70 | BH9: 70 | BI9: 70 | BJ9: 70 | BK9: 70 | BL9: 70 | BM9: 70 | BN9: 70 | BO9: 70 | BP9: 70 | BQ9: 70 | BR9: 70 | BS9: 70 | BT9: 70 | BU9: 70 | BV9: 70.00
A10: Fee Weso % | B10: 30 | C10: 30 | D10: 30 | E10: 30 | F10: 30 | G10: 30 | H10: 30 | I10: 30 | J10: 30 | K10: 30 | L10: 30 | M10: 30 | N10: 30 | O10: 30 | P10: 30 | Q10: 30 | R10: 30 | S10: 30 | T10: 30 | U10: 30 | V10: 30 | W10: 30 | X10: 30 | Y10: 30 | Z10: 30 | AA10: 30 | AB10: 30 | AC10: 30 | AD10: 30 | AE10: 30 | AF10: 30 | AG10: 30 | AH10: 30 | AI10: 30 | AJ10: 30 | AK10: 30 | AL10: 30 | AM10: 30 | AN10: 30 | AO10: 30 | AP10: 30 | AQ10: 30 | AR10: 30 | AS10: 30 | AT10: 30 | AU10: 30 | AV10: 30 | AW10: 30 | AX10: 30 | AY10: 30 | AZ10: 30 | BA10: 30 | BB10: 30 | BC10: 30 | BD10: 30 | BE10: 30 | BF10: 30 | BG10: 30 | BH10: 30 | BI10: 30 | BJ10: 30 | BK10: 30 | BL10: 30 | BM10: 30 | BN10: 30 | BO10: 30 | BP10: 30 | BQ10: 30 | BR10: 30 | BS10: 30 | BT10: 30 | BU10: 30 | BV10: 30.00
